<?xml version="1.0" encoding="UTF-8"?>
<testng-results ignored="0" total="3" passed="2" failed="1" skipped="0">
  <reporter-output>
  </reporter-output>
  <suite started-at="2024-12-18T18:09:33Z" name="Default suite" finished-at="2024-12-18T18:09:33Z" duration-ms="80">
    <groups>
    </groups>
    <test started-at="2024-12-18T18:09:33Z" name="Default test" finished-at="2024-12-18T18:09:33Z" duration-ms="80">
      <class name="Testng_testclasses.Testng_Asserts">
        <test-method signature="testArrays()[pri:0, instance:Testng_testclasses.Testng_Asserts@6155d082]" started-at="2024-12-18T23:39:33Z" name="testArrays" finished-at="2024-12-18T23:39:33Z" duration-ms="45" status="PASS">
          <reporter-output>
          </reporter-output>
        </test-method> <!-- testArrays -->
        <test-method signature="testString()[pri:0, instance:Testng_testclasses.Testng_Asserts@6155d082]" started-at="2024-12-18T23:39:33Z" name="testString" finished-at="2024-12-18T23:39:33Z" duration-ms="3" status="PASS">
          <reporter-output>
          </reporter-output>
        </test-method> <!-- testString -->
        <test-method signature="testSum()[pri:0, instance:Testng_testclasses.Testng_Asserts@6155d082]" started-at="2024-12-18T23:39:33Z" name="testSum" finished-at="2024-12-18T23:39:33Z" duration-ms="8" status="FAIL">
          <exception class="java.lang.AssertionError">
            <message>
              <![CDATA[The following asserts failed:
	expected [2] but found [3]]]>
            </message>
            <full-stacktrace>
              <![CDATA[java.lang.AssertionError: The following asserts failed:
	expected [2] but found [3]
	at org.testng.asserts.SoftAssert.assertAll(SoftAssert.java:43)
	at Testng_testclasses.Testng_Asserts.testSum(Testng_Asserts.java:19)
	at java.base/jdk.internal.reflect.DirectMethodHandleAccessor.invoke(DirectMethodHandleAccessor.java:103)
	at java.base/java.lang.reflect.Method.invoke(Method.java:580)
	at org.testng.internal.MethodInvocationHelper.invokeMethod(MethodInvocationHelper.java:108)
	at org.testng.internal.Invoker.invokeMethod(Invoker.java:661)
	at org.testng.internal.Invoker.invokeTestMethod(Invoker.java:869)
	at org.testng.internal.Invoker.invokeTestMethods(Invoker.java:1193)
	at org.testng.internal.TestMethodWorker.invokeTestMethods(TestMethodWorker.java:126)
	at org.testng.internal.TestMethodWorker.run(TestMethodWorker.java:109)
	at org.testng.TestRunner.privateRun(TestRunner.java:744)
	at org.testng.TestRunner.run(TestRunner.java:602)
	at org.testng.SuiteRunner.runTest(SuiteRunner.java:380)
	at org.testng.SuiteRunner.runSequentially(SuiteRunner.java:375)
	at org.testng.SuiteRunner.privateRun(SuiteRunner.java:340)
	at org.testng.SuiteRunner.run(SuiteRunner.java:289)
	at org.testng.SuiteRunnerWorker.runSuite(SuiteRunnerWorker.java:52)
	at org.testng.SuiteRunnerWorker.run(SuiteRunnerWorker.java:86)
	at org.testng.TestNG.runSuitesSequentially(TestNG.java:1301)
	at org.testng.TestNG.runSuitesLocally(TestNG.java:1226)
	at org.testng.TestNG.runSuites(TestNG.java:1144)
	at org.testng.TestNG.run(TestNG.java:1115)
	at org.testng.remote.AbstractRemoteTestNG.run(AbstractRemoteTestNG.java:115)
	at org.testng.remote.RemoteTestNG.initAndRun(RemoteTestNG.java:293)
	at org.testng.remote.RemoteTestNG.main(RemoteTestNG.java:91)
]]>
            </full-stacktrace>
          </exception> <!-- java.lang.AssertionError -->
          <reporter-output>
          </reporter-output>
        </test-method> <!-- testSum -->
      </class> <!-- Testng_testclasses.Testng_Asserts -->
    </test> <!-- Default test -->
  </suite> <!-- Default suite -->
</testng-results>
