<?xml version="1.0" encoding="UTF-8"?>
<testng-results ignored="0" total="4" passed="2" failed="2" skipped="0">
  <reporter-output>
  </reporter-output>
  <suite started-at="2024-12-20T21:29:00Z" name="Listeners TestSuite" finished-at="2024-12-20T21:29:01Z" duration-ms="159">
    <groups>
    </groups>
    <test started-at="2024-12-20T21:29:00Z" name="Application test 1" finished-at="2024-12-20T21:29:00Z" duration-ms="42">
      <class name="Testng_testclasses.Testng_ListenersTest1">
        <test-method is-config="true" signature="beforeClass()[pri:0, instance:Testng_testclasses.Testng_ListenersTest1@61001b64]" started-at="2024-12-21T02:59:00Z" name="beforeClass" finished-at="2024-12-21T02:59:00Z" duration-ms="8" status="PASS">
          <reporter-output>
          </reporter-output>
        </test-method> <!-- beforeClass -->
        <test-method signature="testMethod1()[pri:0, instance:Testng_testclasses.Testng_ListenersTest1@61001b64]" started-at="2024-12-21T02:59:00Z" name="testMethod1" finished-at="2024-12-21T02:59:00Z" duration-ms="9" status="PASS">
          <reporter-output>
          </reporter-output>
        </test-method> <!-- testMethod1 -->
        <test-method signature="testMethod2()[pri:0, instance:Testng_testclasses.Testng_ListenersTest1@61001b64]" started-at="2024-12-21T02:59:00Z" name="testMethod2" finished-at="2024-12-21T02:59:00Z" duration-ms="2" status="FAIL">
          <exception class="java.lang.AssertionError">
            <message>
              <![CDATA[expected [true] but found [false]]]>
            </message>
            <full-stacktrace>
              <![CDATA[java.lang.AssertionError: expected [true] but found [false]
	at org.testng.Assert.fail(Assert.java:93)
	at org.testng.Assert.failNotEquals(Assert.java:512)
	at org.testng.Assert.assertTrue(Assert.java:41)
	at org.testng.Assert.assertTrue(Assert.java:51)
	at Testng_testclasses.Testng_ListenersTest1.testMethod2(Testng_ListenersTest1.java:31)
	at java.base/jdk.internal.reflect.DirectMethodHandleAccessor.invoke(DirectMethodHandleAccessor.java:103)
	at java.base/java.lang.reflect.Method.invoke(Method.java:580)
	at org.testng.internal.MethodInvocationHelper.invokeMethod(MethodInvocationHelper.java:108)
	at org.testng.internal.Invoker.invokeMethod(Invoker.java:661)
	at org.testng.internal.Invoker.invokeTestMethod(Invoker.java:869)
	at org.testng.internal.Invoker.invokeTestMethods(Invoker.java:1193)
	at org.testng.internal.TestMethodWorker.invokeTestMethods(TestMethodWorker.java:126)
	at org.testng.internal.TestMethodWorker.run(TestMethodWorker.java:109)
	at org.testng.TestRunner.privateRun(TestRunner.java:744)
	at org.testng.TestRunner.run(TestRunner.java:602)
	at org.testng.SuiteRunner.runTest(SuiteRunner.java:380)
	at org.testng.SuiteRunner.runSequentially(SuiteRunner.java:375)
	at org.testng.SuiteRunner.privateRun(SuiteRunner.java:340)
	at org.testng.SuiteRunner.run(SuiteRunner.java:289)
	at org.testng.SuiteRunnerWorker.runSuite(SuiteRunnerWorker.java:52)
	at org.testng.SuiteRunnerWorker.run(SuiteRunnerWorker.java:86)
	at org.testng.TestNG.runSuitesSequentially(TestNG.java:1301)
	at org.testng.TestNG.runSuitesLocally(TestNG.java:1226)
	at org.testng.TestNG.runSuites(TestNG.java:1144)
	at org.testng.TestNG.run(TestNG.java:1115)
	at org.testng.remote.AbstractRemoteTestNG.run(AbstractRemoteTestNG.java:115)
	at org.testng.remote.RemoteTestNG.initAndRun(RemoteTestNG.java:293)
	at org.testng.remote.RemoteTestNG.main(RemoteTestNG.java:91)
]]>
            </full-stacktrace>
          </exception> <!-- java.lang.AssertionError -->
          <reporter-output>
          </reporter-output>
        </test-method> <!-- testMethod2 -->
        <test-method is-config="true" signature="afterClass()[pri:0, instance:Testng_testclasses.Testng_ListenersTest1@61001b64]" started-at="2024-12-21T02:59:00Z" name="afterClass" finished-at="2024-12-21T02:59:00Z" duration-ms="1" status="PASS">
          <reporter-output>
          </reporter-output>
        </test-method> <!-- afterClass -->
      </class> <!-- Testng_testclasses.Testng_ListenersTest1 -->
    </test> <!-- Application test 1 -->
    <test started-at="2024-12-20T21:29:01Z" name="Application test 2" finished-at="2024-12-20T21:29:01Z" duration-ms="10">
      <class name="Testng_testclasses.Testng_ListenersTest2">
        <test-method signature="testMethod1()[pri:0, instance:Testng_testclasses.Testng_ListenersTest2@5a45133e]" started-at="2024-12-21T02:59:01Z" name="testMethod1" finished-at="2024-12-21T02:59:01Z" duration-ms="2" status="PASS">
          <reporter-output>
          </reporter-output>
        </test-method> <!-- testMethod1 -->
        <test-method is-config="true" signature="beforeClass()[pri:0, instance:Testng_testclasses.Testng_ListenersTest2@5a45133e]" started-at="2024-12-21T02:59:01Z" name="beforeClass" finished-at="2024-12-21T02:59:01Z" duration-ms="0" status="PASS">
          <reporter-output>
          </reporter-output>
        </test-method> <!-- beforeClass -->
        <test-method signature="testMethod2()[pri:0, instance:Testng_testclasses.Testng_ListenersTest2@5a45133e]" started-at="2024-12-21T02:59:01Z" name="testMethod2" finished-at="2024-12-21T02:59:01Z" duration-ms="1" status="FAIL">
          <exception class="java.lang.AssertionError">
            <message>
              <![CDATA[expected [true] but found [false]]]>
            </message>
            <full-stacktrace>
              <![CDATA[java.lang.AssertionError: expected [true] but found [false]
	at org.testng.Assert.fail(Assert.java:93)
	at org.testng.Assert.failNotEquals(Assert.java:512)
	at org.testng.Assert.assertTrue(Assert.java:41)
	at org.testng.Assert.assertTrue(Assert.java:51)
	at Testng_testclasses.Testng_ListenersTest2.testMethod2(Testng_ListenersTest2.java:31)
	at java.base/jdk.internal.reflect.DirectMethodHandleAccessor.invoke(DirectMethodHandleAccessor.java:103)
	at java.base/java.lang.reflect.Method.invoke(Method.java:580)
	at org.testng.internal.MethodInvocationHelper.invokeMethod(MethodInvocationHelper.java:108)
	at org.testng.internal.Invoker.invokeMethod(Invoker.java:661)
	at org.testng.internal.Invoker.invokeTestMethod(Invoker.java:869)
	at org.testng.internal.Invoker.invokeTestMethods(Invoker.java:1193)
	at org.testng.internal.TestMethodWorker.invokeTestMethods(TestMethodWorker.java:126)
	at org.testng.internal.TestMethodWorker.run(TestMethodWorker.java:109)
	at org.testng.TestRunner.privateRun(TestRunner.java:744)
	at org.testng.TestRunner.run(TestRunner.java:602)
	at org.testng.SuiteRunner.runTest(SuiteRunner.java:380)
	at org.testng.SuiteRunner.runSequentially(SuiteRunner.java:375)
	at org.testng.SuiteRunner.privateRun(SuiteRunner.java:340)
	at org.testng.SuiteRunner.run(SuiteRunner.java:289)
	at org.testng.SuiteRunnerWorker.runSuite(SuiteRunnerWorker.java:52)
	at org.testng.SuiteRunnerWorker.run(SuiteRunnerWorker.java:86)
	at org.testng.TestNG.runSuitesSequentially(TestNG.java:1301)
	at org.testng.TestNG.runSuitesLocally(TestNG.java:1226)
	at org.testng.TestNG.runSuites(TestNG.java:1144)
	at org.testng.TestNG.run(TestNG.java:1115)
	at org.testng.remote.AbstractRemoteTestNG.run(AbstractRemoteTestNG.java:115)
	at org.testng.remote.RemoteTestNG.initAndRun(RemoteTestNG.java:293)
	at org.testng.remote.RemoteTestNG.main(RemoteTestNG.java:91)
]]>
            </full-stacktrace>
          </exception> <!-- java.lang.AssertionError -->
          <reporter-output>
          </reporter-output>
        </test-method> <!-- testMethod2 -->
        <test-method is-config="true" signature="afterClass()[pri:0, instance:Testng_testclasses.Testng_ListenersTest2@5a45133e]" started-at="2024-12-21T02:59:01Z" name="afterClass" finished-at="2024-12-21T02:59:01Z" duration-ms="0" status="PASS">
          <reporter-output>
          </reporter-output>
        </test-method> <!-- afterClass -->
      </class> <!-- Testng_testclasses.Testng_ListenersTest2 -->
    </test> <!-- Application test 2 -->
  </suite> <!-- Listeners TestSuite -->
</testng-results>
